2024-03-18 17:40:33,541 - root - INFO: Сообщение okidoki успешно отправлено!
2024-03-18 17:45:29,331 - root - INFO: Сообщение okidoki успешно отправлено!
2024-03-19 10:23:13,059 - telegram.vendor.ptb_urllib3.urllib3.connectionpool - WARNING: Retrying (Retry(total=2, connect=None, read=None, redirect=None)) after connection broken by 'NewConnectionError('<telegram.vendor.ptb_urllib3.urllib3.connection.VerifiedHTTPSConnection object at 0x00000268AF987C10>: Failed to establish a new connection: [Errno 11001] getaddrinfo failed')': /bot6796591440:AAFesDsDK5wU0jvENEHRaYFynz6e7lJEk7g/sendMessage
2024-03-19 10:23:13,060 - telegram.vendor.ptb_urllib3.urllib3.connectionpool - WARNING: Retrying (Retry(total=1, connect=None, read=None, redirect=None)) after connection broken by 'NewConnectionError('<telegram.vendor.ptb_urllib3.urllib3.connection.VerifiedHTTPSConnection object at 0x00000268AF987D30>: Failed to establish a new connection: [Errno 11001] getaddrinfo failed')': /bot6796591440:AAFesDsDK5wU0jvENEHRaYFynz6e7lJEk7g/sendMessage
2024-03-19 10:23:13,067 - telegram.vendor.ptb_urllib3.urllib3.connectionpool - WARNING: Retrying (Retry(total=0, connect=None, read=None, redirect=None)) after connection broken by 'NewConnectionError('<telegram.vendor.ptb_urllib3.urllib3.connection.VerifiedHTTPSConnection object at 0x00000268AF987E80>: Failed to establish a new connection: [Errno 11001] getaddrinfo failed')': /bot6796591440:AAFesDsDK5wU0jvENEHRaYFynz6e7lJEk7g/sendMessage
2024-03-19 10:25:04,801 - root - ERROR: Сбой в работе программы: 
2024-03-19 10:25:04,802 - telegram.vendor.ptb_urllib3.urllib3.connectionpool - WARNING: Retrying (Retry(total=2, connect=None, read=None, redirect=None)) after connection broken by 'NewConnectionError('<telegram.vendor.ptb_urllib3.urllib3.connection.VerifiedHTTPSConnection object at 0x000002737C628CD0>: Failed to establish a new connection: [Errno 11001] getaddrinfo failed')': /bot6796591440:AAFesDsDK5wU0jvENEHRaYFynz6e7lJEk7g/sendMessage
2024-03-19 10:25:04,803 - telegram.vendor.ptb_urllib3.urllib3.connectionpool - WARNING: Retrying (Retry(total=1, connect=None, read=None, redirect=None)) after connection broken by 'NewConnectionError('<telegram.vendor.ptb_urllib3.urllib3.connection.VerifiedHTTPSConnection object at 0x000002737C628DF0>: Failed to establish a new connection: [Errno 11001] getaddrinfo failed')': /bot6796591440:AAFesDsDK5wU0jvENEHRaYFynz6e7lJEk7g/sendMessage
2024-03-19 10:25:04,804 - telegram.vendor.ptb_urllib3.urllib3.connectionpool - WARNING: Retrying (Retry(total=0, connect=None, read=None, redirect=None)) after connection broken by 'NewConnectionError('<telegram.vendor.ptb_urllib3.urllib3.connection.VerifiedHTTPSConnection object at 0x000002737C628F40>: Failed to establish a new connection: [Errno 11001] getaddrinfo failed')': /bot6796591440:AAFesDsDK5wU0jvENEHRaYFynz6e7lJEk7g/sendMessage
2024-03-19 10:33:19,257 - root - ERROR: Сбой в работе программы: HTTPSConnectionPool(host='practicum.yandex.ru', port=443): Max retries exceeded with url: /api/user_api/homework_statuses/?from_date=0 (Caused by NewConnectionError('<urllib3.connection.HTTPSConnection object at 0x00000286C8278CD0>: Failed to establish a new connection: [Errno 11001] getaddrinfo failed'))
2024-03-19 10:33:19,258 - telegram.vendor.ptb_urllib3.urllib3.connectionpool - WARNING: Retrying (Retry(total=2, connect=None, read=None, redirect=None)) after connection broken by 'NewConnectionError('<telegram.vendor.ptb_urllib3.urllib3.connection.VerifiedHTTPSConnection object at 0x00000286C8278820>: Failed to establish a new connection: [Errno 11001] getaddrinfo failed')': /bot6796591440:AAFesDsDK5wU0jvENEHRaYFynz6e7lJEk7g/sendMessage
2024-03-19 10:33:19,260 - telegram.vendor.ptb_urllib3.urllib3.connectionpool - WARNING: Retrying (Retry(total=1, connect=None, read=None, redirect=None)) after connection broken by 'NewConnectionError('<telegram.vendor.ptb_urllib3.urllib3.connection.VerifiedHTTPSConnection object at 0x00000286C80206D0>: Failed to establish a new connection: [Errno 11001] getaddrinfo failed')': /bot6796591440:AAFesDsDK5wU0jvENEHRaYFynz6e7lJEk7g/sendMessage
2024-03-19 10:33:19,260 - telegram.vendor.ptb_urllib3.urllib3.connectionpool - WARNING: Retrying (Retry(total=0, connect=None, read=None, redirect=None)) after connection broken by 'NewConnectionError('<telegram.vendor.ptb_urllib3.urllib3.connection.VerifiedHTTPSConnection object at 0x00000286C82B4100>: Failed to establish a new connection: [Errno 11001] getaddrinfo failed')': /bot6796591440:AAFesDsDK5wU0jvENEHRaYFynz6e7lJEk7g/sendMessage
2024-03-19 10:34:29,458 - root - ERROR: Сбой в работе программы: HTTPSConnectionPool(host='practicum.yandex.ru', port=443): Max retries exceeded with url: /api/user_api/homework_statuses/?from_date=0 (Caused by NewConnectionError('<urllib3.connection.HTTPSConnection object at 0x0000018F55647AF0>: Failed to establish a new connection: [Errno 11001] getaddrinfo failed'))
2024-03-19 10:34:29,459 - telegram.vendor.ptb_urllib3.urllib3.connectionpool - WARNING: Retrying (Retry(total=2, connect=None, read=None, redirect=None)) after connection broken by 'NewConnectionError('<telegram.vendor.ptb_urllib3.urllib3.connection.VerifiedHTTPSConnection object at 0x0000018F55647F10>: Failed to establish a new connection: [Errno 11001] getaddrinfo failed')': /bot6796591440:AAFesDsDK5wU0jvENEHRaYFynz6e7lJEk7g/sendMessage
2024-03-19 10:34:29,460 - telegram.vendor.ptb_urllib3.urllib3.connectionpool - WARNING: Retrying (Retry(total=1, connect=None, read=None, redirect=None)) after connection broken by 'NewConnectionError('<telegram.vendor.ptb_urllib3.urllib3.connection.VerifiedHTTPSConnection object at 0x0000018F55675070>: Failed to establish a new connection: [Errno 11001] getaddrinfo failed')': /bot6796591440:AAFesDsDK5wU0jvENEHRaYFynz6e7lJEk7g/sendMessage
2024-03-19 10:34:29,462 - telegram.vendor.ptb_urllib3.urllib3.connectionpool - WARNING: Retrying (Retry(total=0, connect=None, read=None, redirect=None)) after connection broken by 'NewConnectionError('<telegram.vendor.ptb_urllib3.urllib3.connection.VerifiedHTTPSConnection object at 0x0000018F556751C0>: Failed to establish a new connection: [Errno 11001] getaddrinfo failed')': /bot6796591440:AAFesDsDK5wU0jvENEHRaYFynz6e7lJEk7g/sendMessage
2024-03-19 10:34:35,676 - root - ERROR: Сбой в работе программы: HTTPSConnectionPool(host='practicum.yandex.ru', port=443): Max retries exceeded with url: /api/user_api/homework_statuses/?from_date=0 (Caused by NewConnectionError('<urllib3.connection.HTTPSConnection object at 0x000001E53A2C7AF0>: Failed to establish a new connection: [Errno 11001] getaddrinfo failed'))
2024-03-19 10:34:35,677 - telegram.vendor.ptb_urllib3.urllib3.connectionpool - WARNING: Retrying (Retry(total=2, connect=None, read=None, redirect=None)) after connection broken by 'NewConnectionError('<telegram.vendor.ptb_urllib3.urllib3.connection.VerifiedHTTPSConnection object at 0x000001E53A2C7F10>: Failed to establish a new connection: [Errno 11001] getaddrinfo failed')': /bot6796591440:AAFesDsDK5wU0jvENEHRaYFynz6e7lJEk7g/sendMessage
2024-03-19 10:34:35,678 - telegram.vendor.ptb_urllib3.urllib3.connectionpool - WARNING: Retrying (Retry(total=1, connect=None, read=None, redirect=None)) after connection broken by 'NewConnectionError('<telegram.vendor.ptb_urllib3.urllib3.connection.VerifiedHTTPSConnection object at 0x000001E53A2F5070>: Failed to establish a new connection: [Errno 11001] getaddrinfo failed')': /bot6796591440:AAFesDsDK5wU0jvENEHRaYFynz6e7lJEk7g/sendMessage
2024-03-19 10:34:35,679 - telegram.vendor.ptb_urllib3.urllib3.connectionpool - WARNING: Retrying (Retry(total=0, connect=None, read=None, redirect=None)) after connection broken by 'NewConnectionError('<telegram.vendor.ptb_urllib3.urllib3.connection.VerifiedHTTPSConnection object at 0x000001E53A2F51C0>: Failed to establish a new connection: [Errno 11001] getaddrinfo failed')': /bot6796591440:AAFesDsDK5wU0jvENEHRaYFynz6e7lJEk7g/sendMessage
2024-03-19 10:35:45,485 - root - ERROR: окококСбой в работе программы: HTTPSConnectionPool(host='practicum.yandex.ru', port=443): Max retries exceeded with url: /api/user_api/homework_statuses/?from_date=0 (Caused by NewConnectionError('<urllib3.connection.HTTPSConnection object at 0x000001C353828AC0>: Failed to establish a new connection: [Errno 11001] getaddrinfo failed'))
2024-03-19 10:35:45,487 - telegram.vendor.ptb_urllib3.urllib3.connectionpool - WARNING: Retrying (Retry(total=2, connect=None, read=None, redirect=None)) after connection broken by 'NewConnectionError('<telegram.vendor.ptb_urllib3.urllib3.connection.VerifiedHTTPSConnection object at 0x000001C353828EE0>: Failed to establish a new connection: [Errno 11001] getaddrinfo failed')': /bot6796591440:AAFesDsDK5wU0jvENEHRaYFynz6e7lJEk7g/sendMessage
2024-03-19 10:35:45,488 - telegram.vendor.ptb_urllib3.urllib3.connectionpool - WARNING: Retrying (Retry(total=1, connect=None, read=None, redirect=None)) after connection broken by 'NewConnectionError('<telegram.vendor.ptb_urllib3.urllib3.connection.VerifiedHTTPSConnection object at 0x000001C353855040>: Failed to establish a new connection: [Errno 11001] getaddrinfo failed')': /bot6796591440:AAFesDsDK5wU0jvENEHRaYFynz6e7lJEk7g/sendMessage
2024-03-19 10:35:45,489 - telegram.vendor.ptb_urllib3.urllib3.connectionpool - WARNING: Retrying (Retry(total=0, connect=None, read=None, redirect=None)) after connection broken by 'NewConnectionError('<telegram.vendor.ptb_urllib3.urllib3.connection.VerifiedHTTPSConnection object at 0x000001C353855190>: Failed to establish a new connection: [Errno 11001] getaddrinfo failed')': /bot6796591440:AAFesDsDK5wU0jvENEHRaYFynz6e7lJEk7g/sendMessage
2024-03-19 10:47:02,127 - root - ERROR: окококСбой в работе программы: HTTPSConnectionPool(host='practicum.yandex.ru', port=443): Max retries exceeded with url: /api/user_api/homework_statuses/?from_date=0 (Caused by NewConnectionError('<urllib3.connection.HTTPSConnection object at 0x00000282CC8A8AC0>: Failed to establish a new connection: [Errno 11001] getaddrinfo failed'))
2024-03-19 10:47:02,128 - telegram.vendor.ptb_urllib3.urllib3.connectionpool - WARNING: Retrying (Retry(total=2, connect=None, read=None, redirect=None)) after connection broken by 'NewConnectionError('<telegram.vendor.ptb_urllib3.urllib3.connection.VerifiedHTTPSConnection object at 0x00000282CC8A8EE0>: Failed to establish a new connection: [Errno 11001] getaddrinfo failed')': /bot6796591440:AAFesDsDK5wU0jvENEHRaYFynz6e7lJEk7g/sendMessage
2024-03-19 10:47:02,130 - telegram.vendor.ptb_urllib3.urllib3.connectionpool - WARNING: Retrying (Retry(total=1, connect=None, read=None, redirect=None)) after connection broken by 'NewConnectionError('<telegram.vendor.ptb_urllib3.urllib3.connection.VerifiedHTTPSConnection object at 0x00000282CC8D5040>: Failed to establish a new connection: [Errno 11001] getaddrinfo failed')': /bot6796591440:AAFesDsDK5wU0jvENEHRaYFynz6e7lJEk7g/sendMessage
2024-03-19 10:47:02,131 - telegram.vendor.ptb_urllib3.urllib3.connectionpool - WARNING: Retrying (Retry(total=0, connect=None, read=None, redirect=None)) after connection broken by 'NewConnectionError('<telegram.vendor.ptb_urllib3.urllib3.connection.VerifiedHTTPSConnection object at 0x00000282CC8D5190>: Failed to establish a new connection: [Errno 11001] getaddrinfo failed')': /bot6796591440:AAFesDsDK5wU0jvENEHRaYFynz6e7lJEk7g/sendMessage
2024-03-19 10:48:32,927 - root - ERROR: окококСбой в работе программы: Сбой в работе программы: Эндпоинт https://practicum.yandex.ru/api/user_api/homewвork_statuses/ недоступен. Код ответа API: 404
2024-03-19 11:15:30,715 - root - ERROR: Сбой в работе программы: Проблемы с соединением, HTTPSConnectionPool(host='practicum.yandex.ru', port=443): Max retries exceeded with url: /api/user_api/homework_statuses/?from_date=0 (Caused by NewConnectionError('<urllib3.connection.HTTPSConnection object at 0x00000202FC8F8CA0>: Failed to establish a new connection: [Errno 11001] getaddrinfo failed'))
2024-03-19 11:15:30,716 - telegram.vendor.ptb_urllib3.urllib3.connectionpool - WARNING: Retrying (Retry(total=2, connect=None, read=None, redirect=None)) after connection broken by 'NewConnectionError('<telegram.vendor.ptb_urllib3.urllib3.connection.VerifiedHTTPSConnection object at 0x00000202FC91D100>: Failed to establish a new connection: [Errno 11001] getaddrinfo failed')': /bot6796591440:AAFesDsDK5wU0jvENEHRaYFynz6e7lJEk7g/sendMessage
2024-03-19 11:15:30,718 - telegram.vendor.ptb_urllib3.urllib3.connectionpool - WARNING: Retrying (Retry(total=1, connect=None, read=None, redirect=None)) after connection broken by 'NewConnectionError('<telegram.vendor.ptb_urllib3.urllib3.connection.VerifiedHTTPSConnection object at 0x00000202FC91D220>: Failed to establish a new connection: [Errno 11001] getaddrinfo failed')': /bot6796591440:AAFesDsDK5wU0jvENEHRaYFynz6e7lJEk7g/sendMessage
2024-03-19 11:15:30,720 - telegram.vendor.ptb_urllib3.urllib3.connectionpool - WARNING: Retrying (Retry(total=0, connect=None, read=None, redirect=None)) after connection broken by 'NewConnectionError('<telegram.vendor.ptb_urllib3.urllib3.connection.VerifiedHTTPSConnection object at 0x00000202FC91D370>: Failed to establish a new connection: [Errno 11001] getaddrinfo failed')': /bot6796591440:AAFesDsDK5wU0jvENEHRaYFynz6e7lJEk7g/sendMessage
2024-03-19 11:39:51,770 - root - ERROR: Сбой в работе программы: Проблемы с соединением, HTTPSConnectionPool(host='practicum.yandex.ru', port=443): Max retries exceeded with url: /api/user_api/homework_statuses/?from_date=0 (Caused by NewConnectionError('<urllib3.connection.HTTPSConnection object at 0x0000027DE3678C40>: Failed to establish a new connection: [Errno 11001] getaddrinfo failed'))
2024-03-19 11:39:51,773 - telegram.vendor.ptb_urllib3.urllib3.connectionpool - WARNING: Retrying (Retry(total=2, connect=None, read=None, redirect=None)) after connection broken by 'NewConnectionError('<telegram.vendor.ptb_urllib3.urllib3.connection.VerifiedHTTPSConnection object at 0x0000027DE369D0A0>: Failed to establish a new connection: [Errno 11001] getaddrinfo failed')': /bot6796591440:AAFesDsDK5wU0jvENEHRaYFynz6e7lJEk7g/sendMessage
2024-03-19 11:39:51,774 - telegram.vendor.ptb_urllib3.urllib3.connectionpool - WARNING: Retrying (Retry(total=1, connect=None, read=None, redirect=None)) after connection broken by 'NewConnectionError('<telegram.vendor.ptb_urllib3.urllib3.connection.VerifiedHTTPSConnection object at 0x0000027DE369D1C0>: Failed to establish a new connection: [Errno 11001] getaddrinfo failed')': /bot6796591440:AAFesDsDK5wU0jvENEHRaYFynz6e7lJEk7g/sendMessage
2024-03-19 11:39:51,775 - telegram.vendor.ptb_urllib3.urllib3.connectionpool - WARNING: Retrying (Retry(total=0, connect=None, read=None, redirect=None)) after connection broken by 'NewConnectionError('<telegram.vendor.ptb_urllib3.urllib3.connection.VerifiedHTTPSConnection object at 0x0000027DE369D310>: Failed to establish a new connection: [Errno 11001] getaddrinfo failed')': /bot6796591440:AAFesDsDK5wU0jvENEHRaYFynz6e7lJEk7g/sendMessage
2024-03-19 11:41:09,433 - root - ERROR: Сбой в работе программы: Проблемы с соединением, HTTPSConnectionPool(host='practicum.yandex.ru', port=443): Max retries exceeded with url: /api/user_api/homework_statuses/?from_date=0 (Caused by NewConnectionError('<urllib3.connection.HTTPSConnection object at 0x000002D1A5108CA0>: Failed to establish a new connection: [Errno 11001] getaddrinfo failed'))
2024-03-19 11:41:09,434 - telegram.vendor.ptb_urllib3.urllib3.connectionpool - WARNING: Retrying (Retry(total=2, connect=None, read=None, redirect=None)) after connection broken by 'NewConnectionError('<telegram.vendor.ptb_urllib3.urllib3.connection.VerifiedHTTPSConnection object at 0x000002D1A512D100>: Failed to establish a new connection: [Errno 11001] getaddrinfo failed')': /bot6796591440:AAFesDsDK5wU0jvENEHRaYFynz6e7lJEk7g/sendMessage
2024-03-19 11:41:09,435 - telegram.vendor.ptb_urllib3.urllib3.connectionpool - WARNING: Retrying (Retry(total=1, connect=None, read=None, redirect=None)) after connection broken by 'NewConnectionError('<telegram.vendor.ptb_urllib3.urllib3.connection.VerifiedHTTPSConnection object at 0x000002D1A512D220>: Failed to establish a new connection: [Errno 11001] getaddrinfo failed')': /bot6796591440:AAFesDsDK5wU0jvENEHRaYFynz6e7lJEk7g/sendMessage
2024-03-19 11:41:09,435 - telegram.vendor.ptb_urllib3.urllib3.connectionpool - WARNING: Retrying (Retry(total=0, connect=None, read=None, redirect=None)) after connection broken by 'NewConnectionError('<telegram.vendor.ptb_urllib3.urllib3.connection.VerifiedHTTPSConnection object at 0x000002D1A512D370>: Failed to establish a new connection: [Errno 11001] getaddrinfo failed')': /bot6796591440:AAFesDsDK5wU0jvENEHRaYFynz6e7lJEk7g/sendMessage
2024-03-19 11:53:06,135 - root - CRITICAL: Отсутствует обязательная переменная окружения: None
2024-03-19 11:59:12,326 - root - ERROR: Сбой в работе программы: name 'current' is not defined
2024-03-19 11:59:23,305 - root - ERROR: Сбой в работе программы: name 'current' is not defined
2024-03-19 12:00:23,500 - root - ERROR: Сбой в работе программы: name 'current_status' is not defined
2024-03-19 12:00:34,498 - root - ERROR: Сбой в работе программы: name 'current_status' is not defined
2024-03-19 12:00:45,187 - root - ERROR: Сбой в работе программы: name 'current_status' is not defined
2024-03-19 12:00:55,973 - root - ERROR: Сбой в работе программы: name 'current_status' is not defined
2024-03-19 12:01:06,703 - root - ERROR: Сбой в работе программы: name 'current_status' is not defined
2024-03-19 12:03:49,245 - root - ERROR: Сбой в работе программы: name 'prev_status' is not defined
2024-03-19 14:49:23,874 - root - ERROR: Сбой в работе программы: Проблемы с соединением, HTTPSConnectionPool(host='practicum.yandex.ru', port=443): Max retries exceeded with url: /api/user_api/homework_statuses/?from_date=0 (Caused by NewConnectionError('<urllib3.connection.HTTPSConnection object at 0x0000017114AB7E80>: Failed to establish a new connection: [Errno 11001] getaddrinfo failed'))
2024-03-19 14:50:45,055 - root - ERROR: Сбой в работе программы: Проблемы с соединением, HTTPSConnectionPool(host='practicum.yandex.ru', port=443): Max retries exceeded with url: /api/user_api/homework_statuses/?from_date=0 (Caused by NewConnectionError('<urllib3.connection.HTTPSConnection object at 0x000002965FDF8E80>: Failed to establish a new connection: [Errno 11001] getaddrinfo failed'))
2024-03-19 15:34:42,598 - root - ERROR: Сбой в работе программы: За указанный период данные не найдены
2024-03-19 15:46:48,340 - urllib3.connectionpool - DEBUG: Starting new HTTPS connection (1): practicum.yandex.ru:443
2024-03-19 15:46:48,940 - urllib3.connectionpool - DEBUG: https://practicum.yandex.ru:443 "GET /api/user_api/homework_statuses/?from_date=1710852408 HTTP/1.1" 200 42
2024-03-19 15:46:48,942 - root - DEBUG: За указанный период данные не найдены
